# 第五章 语句

## 简单语句

- **表达式语句**：一个表达式末尾加上分号，就变成了表达式语句。
- **空语句**：只有一个单独的分号。
- **复合语句（块）**：用花括号 `{}`包裹起来的语句和声明的序列。一个块就是一个作用域。

## 条件语句

- **悬垂else**（dangling else）：用来描述在嵌套的`if else`语句中，如果`if`比`else`多时如何处理的问题。C++使用的方法是`else`匹配最近没有配对的`if`。
- `switch-case`



## 迭代语句

- **while**：当不确定到底要迭代多少次时，使用 `while`循环比较合适，比如读取输入的内容。
- **for**： `for`语句可以省略掉 `init-statement`， `condition`和 `expression`的任何一个；**甚至全部**。
- **范围for**： `for (declaration: expression) statement`
- **do-while**

```c++
do
    statement
while (condition);
```

计算*condition*的值之前会先执行一次*statement*，*condition*不能为空。如果*condition*的值为`false`，循环终止，否则重复执行*statement*。

因为`do-while`语句先执行语句或块，再判断条件，所以不允许在条件部分定义变量。

## 跳转语句

- **break**：`break`语句负责终止离它最近的`while`、`do while`、`for`或者`switch`语句，并从这些语句之后的第一条语句开始继续执行。

  `break`语句中止当前的控制流

- **continue**：终止最近的循环中的当前迭代并立即开始下一次迭代。只能在`while`、`do while`、`for`循环的内部。

## try语句块和异常处理

​       异常（exception）是指程序运行时的反常行为，这些行为超出了函数正常功能的范围。当程序的某一部分检测到一个它无法处理的问题时，需要使用异常处理（exception handling）。

异常处理包括：

- **throw表达式(throw expression)**：异常检测部分使用 `throw`表达式来表示它遇到了无法处理的问题。我们说 `throw`引发 `raise`了异常。
- **try语句块**：以 `try`关键词开始，以一个或多个 `catch`字句结束。 `try`语句块中的代码抛出的异常通常会被某个 `catch`捕获并处理。 `catch`子句也被称为**异常处理代码**。
- **异常类**：用于在 `throw`表达式和相关的 `catch`子句之间传递异常的具体信息。

### throw表达式（A throw Expression）

`throw`表达式包含关键字`throw`和紧随其后的一个表达式，其中表达式的类型就是抛出的异常类型。

```c++
// 检查两本书item1  item2的isbn是否一样
if(item1.isbn() != item2.isbn()){
    throw runtime_error("Data must refer to same ISBN");
}
//如果程序执行到这里，表示两者isbn是一样的
cout << item1 + item2 << endl;
```

如果`item`不一样就抛出一个异常，该异常是类型`runtime_error`的对象。抛出异常将终止当前的函数，并将控制权转交给能处理该异常的代码。



### try语句块（The try Block）

`try`语句块的通用形式：

```c++
try
{
    program-statements
}
catch (exception-declaration)
{
    handler-statements
}
catch (exception-declaration)
{
    handler-statements
} // . . .
```

跟在`try`块之后的是一个或多个`catch`子句。`catch`子句包括三部分：`catch`关键字、括号内一个（可能未命名）对象的声明（称作**异常声明，exception declaration** ）以及一个块。

```c++
while (cin >> item1 >> item2) {
		try {
			if(item1.isbn() != item2.isbn())   // 如果不同抛出异常
				throw std::runtime_error("Data must refer to same ISBN");
			cout << item1 + item2 << endl;    // 相同处理
		}
		catch(std::runtime_error err){
			cout << err.what();
			cout << "\nTry Again?Enter y or n" << endl;
			char c;
			cin >> c;
			if (!cin || c == 'n') {
				break;
			}
		}
	}
```

`try`语句块中的*program-statements*组成程序的正常逻辑，其内部声明的变量在块外无法访问，即使在`catch`子句中也不行。`catch`子句包含关键字`catch`、括号内一个对象的声明（异常声明，exception declaration）和一个块。当选中了某个`catch`子句处理异常后，执行与之对应的块。`catch`一旦完成，程序会跳过剩余的所有`catch`子句，继续执行后面的语句。

如果最终没能找到与异常相匹配的`catch`子句，程序会执行名为`terminate`的标准库函数。该函数的行为与系统有关，一般情况下，执行该函数将导致程序非正常退出。类似的，如果一段程序没有`try`语句块且发生了异常，系统也会调用`terminate`函数并终止当前程序的执行。

### 标准异常（Standard Exceptions）

异常类分别定义在4个头文件中：

- 头文件*exception*定义了最通用的异常类`exception`。它只报告异常的发生，不提供任何额外信息。
- 头文件*stdexcept*定义了几种常用的异常类。

| 异常类             | 信息                                           |
| ------------------ | ---------------------------------------------- |
| `exception`        | 最常见的问题                                   |
| `runtime_error`    | 只有在运行时才检测出的问题                     |
| `range_error`      | 运行时错误：生成的结果超出了有意义的值域范围   |
| `overflow_error`   | 运行时错误：计算上溢                           |
| `underflow_error`  | 运行时错误：计算下溢                           |
| `logic_error`      | 程序逻辑错误                                   |
| `domain_error`     | 逻辑错误：参数对应的结果值不存在               |
| `invalid_argument` | 逻辑错误：无效参数                             |
| `length_error`     | 逻辑错误：试图创建一个超出该类型最大长度的对象 |
| `out_of_range`     | 逻辑错误：使用一个超出有效范围的值             |

- 头文件*new*定义了`bad_alloc`异常类。
- 头文件*type_info*定义了`bad_cast`异常类。

- 只能以**默认初始化**的方式初始化`exception`、`bad_alloc`、`bad_cast`对象，不允许为这些对象提供初始值。

  其他异常类型的行为与上述的相反。应该使用`string`对象或者C风格字符串初始化这些类型的对象，但是不允许使用默认初始化的方式。当创建此类对象时必须提供初始值，该初始值含有错误相关的信息。

- 异常类型只定义了一个名为`what`的成员函数，该函数没有任何参数，返回值是一个指向`C`风格字符串的`const char*`。该字符串目的是提供关于异常的一些文本信息。
  - 如果异常类型有一个字符串初始值，则`what`返回该字符串。
  
  - 对于其他无初始值的异常类型来说，`what`返回的内容由编译器决定。
  
    

e.g.i,j整数相除  j=0 异常： 

```c++
#include <iostream>
#include <stdexcept>
int main(void) {
    int i, j;
    std::cout << "Please input i and j:";
    while (std::cin >> i >> j) {
        try {
            if (j == 0) {
                throw std::runtime_error("divisor is 0");
            }
            std::cout << i / j << std::endl;
            std::cout << "\nPlease input i and j:(test1)";
        }
        catch (std::runtime_error err) {
            std::cout << err.what() << "\nTry again? y or n:";
            char ch;
            std::cin >> ch;
            if (!std::cin || ch != 'y') {
                break;
            }
            std::cout << "Please input i and j:(test2)";
        }
    }
    return 0;
}
```

